<?xml version="1.0" encoding="utf-8"?>
<!-- =================================================================================== -->
<!-- |    This document was autogenerated by xacro from abb.xacro                      | -->
<!-- |    EDITING THIS FILE BY HAND IS NOT RECOMMENDED                                 | -->
<!-- =================================================================================== -->
<robot name="abb">
  <link name="base_link">
    <visual>
      <origin rpy="0 0 0" xyz="0 0 0"/>
      <geometry>
        <mesh filename="package://meshes/base_link.stl" scale="0.001 0.001 0.001"/>
      </geometry>
    </visual>
    <collision>
      <origin rpy="0 0 0" xyz="0 0 0"/>
      <geometry>
        <mesh filename="package://meshes/base_link.stl" scale="0.001 0.001 0.001"/>
      </geometry>
    </collision>
  </link>
  <link name="link_one_1">
    <visual>
      <origin rpy="0 0 0" xyz="-0.0 -0.166 -0.0"/>
      <geometry>
        <mesh filename="package://meshes/link_one_1.stl" scale="0.001 0.001 0.001"/>
      </geometry>
    </visual>
    <collision>
      <origin rpy="0 0 0" xyz="-0.0 -0.166 -0.0"/>
      <geometry>
        <mesh filename="package://meshes/link_one_1.stl" scale="0.001 0.001 0.001"/>
      </geometry>
    </collision>
  </link>
  <link name="link_two_1">
    <visual>
      <origin rpy="0 0 0" xyz="-0.0595 -0.288 8e-06"/>
      <geometry>
        <mesh filename="package://meshes/link_two_1.stl" scale="0.001 0.001 0.001"/>
      </geometry>
    </visual>
    <collision>
      <origin rpy="0 0 0" xyz="-0.0595 -0.288 8e-06"/>
      <geometry>
        <mesh filename="package://meshes/link_two_1.stl" scale="0.001 0.001 0.001"/>
      </geometry>
    </collision>
  </link>
  <link name="link_three_1">
    <visual>
      <origin rpy="0 0 0" xyz="0.05 -0.558 -3.3e-05"/>
      <geometry>
        <mesh filename="package://meshes/link_three_1.stl" scale="0.001 0.001 0.001"/>
      </geometry>
    </visual>
    <collision>
      <origin rpy="0 0 0" xyz="0.05 -0.558 -3.3e-05"/>
      <geometry>
        <mesh filename="package://meshes/link_three_1.stl" scale="0.001 0.001 0.001"/>
      </geometry>
    </collision>
  </link>
  <link name="link_four_1">
    <visual>
      <origin rpy="0 0 0" xyz="-2e-05 -0.627905 -0.14967"/>
      <geometry>
        <mesh filename="package://meshes/link_four_1.stl" scale="0.001 0.001 0.001"/>
      </geometry>
    </visual>
    <collision>
      <origin rpy="0 0 0" xyz="-2e-05 -0.627905 -0.14967"/>
      <geometry>
        <mesh filename="package://meshes/link_four_1.stl" scale="0.001 0.001 0.001"/>
      </geometry>
    </collision>
  </link>
  <link name="link_five_1">
    <visual>
      <origin rpy="0 0 0" xyz="0.03096 -0.627832 -0.302075"/>
      <geometry>
        <mesh filename="package://meshes/link_five_1.stl" scale="0.001 0.001 0.001"/>
      </geometry>
    </visual>
    <collision>
      <origin rpy="0 0 0" xyz="0.03096 -0.627832 -0.302075"/>
      <geometry>
        <mesh filename="package://meshes/link_five_1.stl" scale="0.001 0.001 0.001"/>
      </geometry>
    </collision>
  </link>
  <link name="link_six_1">
    <visual>
      <origin rpy="0 0 0" xyz="-4.8e-05 -0.627831 -0.36107"/>
      <geometry>
        <mesh filename="package://meshes/link_six_1.stl" scale="0.001 0.001 0.001"/>
      </geometry>
    </visual>
    <collision>
      <origin rpy="0 0 0" xyz="-4.8e-05 -0.627831 -0.36107"/>
      <geometry>
        <mesh filename="package://meshes/link_six_1.stl" scale="0.001 0.001 0.001"/>
      </geometry>
    </collision>
  </link>
  <joint name="Revolute 1" type="continuous">
    <origin rpy="0 0 0" xyz="0.0 0.166 0.0"/>
    <parent link="base_link"/>
    <child link="link_one_1"/>
    <axis xyz="0 -1 0"/>
  </joint>
  <joint name="Revolute 2" type="continuous">
    <origin rpy="0 0 0" xyz="0.0595 0.122 -8e-06"/>
    <parent link="link_one_1"/>
    <child link="link_two_1"/>
    <axis xyz="-1 0 0"/>
  </joint>
  <joint name="Revolute 3" type="continuous">
    <origin rpy="0 0 0" xyz="-0.1095 0.27 4.1e-05"/>
    <parent link="link_two_1"/>
    <child link="link_three_1"/>
    <axis xyz="-1 0 0"/>
  </joint>
  <joint name="Revolute 4" type="continuous">
    <origin rpy="0 0 0" xyz="0.05002 0.069905 0.149637"/>
    <parent link="link_three_1"/>
    <child link="link_four_1"/>
    <axis xyz="0 0 1"/>
  </joint>
  <joint name="Revolute 5" type="continuous">
    <origin rpy="0 0 0" xyz="-0.03098 -7.3e-05 0.152405"/>
    <parent link="link_four_1"/>
    <child link="link_five_1"/>
    <axis xyz="1 0 0"/>
  </joint>
  <joint name="Revolute 6" type="continuous">
    <origin rpy="0 0 0" xyz="0.031008 -1e-06 0.058995"/>
    <parent link="link_five_1"/>
    <child link="link_six_1"/>
    <axis xyz="0 0 1"/>
  </joint>
</robot>

